Workbook

Sheet Return of investment 
B3: System Size(KW) | C3: =Quotation!C1/1000 -> 6
H5: Slab Consumption < 500 kWh | N5: Slab Consumption > 500 kWh | T5: Slab Consumption > 500 kWh
H6: FROM | I6: TO | J6: Rate | K6: kWh consumed | L6: Slab rate | N6: FROM | O6: TO | P6: Rate | Q6: kWh consumed | R6: Slab rate | T6: FROM | U6: TO | V6: Rate | W6: kWh consumed | X6: Slab rate
B7: System cost | C7: =Quotation!K16 -> 380432.18 | E7: Daily generation(KW) | F7: 25.9 | H7: 401 | I7: 500 | J7: 6.3 | L7: =K7*J7 -> 0 | N7: 1001 | O7: 9999 | P7: 11.55 | Q7: =if(($F$9-SUM(Q8:Q$13))-($O7-($N7-1))>0,($O7-($N7-1)),($F$9-SUM(Q8:Q$13))) -> 575.58333 | R7: =Q7*P7 -> 6647.9875 | T7: 1001 | U7: 9999 | V7: 11.55 | W7: =LET( remaining,$W$16-SUM(X8:X13), result,IF(remaining<=X7,remaining/$V7,(U7-T7)+1), MAX(0,result) ) -> 2248.4848 | X7: =$V7*($U7-($T7-1)) -> 103938.45
B8: Subsidy | C8: =(if((Quotation!F17*C3)>78000,78000,(Quotation!F17*C3))) -> 78000 | E8: Annual Generation (KW) | F8: =F7*365 -> 9453.5 | H8: 201 | I8: 400 | J8: 4.7 | K8: 200 | L8: =K8*J8 -> 940 | N8: 801 | O8: 1000 | P8: 10.5 | Q8: =if(($F$9-SUM(Q9:Q$13))-($O8-($N8-1))>0,($O8-($N8-1)),($F$9-SUM(Q9:Q$13))) -> 200 | R8: =Q8*P8 -> 2100 | T8: 801 | U8: 1000 | V8: 10.5 | W8: =LET( remaining,$W$16-SUM(X9:X$13), result,IF(remaining<=X8,remaining/$V8,(U8-T8)+1), MAX(0,result) ) -> 200 | X8: =$V8*($U8-($T8-1)) -> 2100
B9: Net Investment | C9: =Quotation!K18 -> 297679.32 | E9: Bi Monthly Generation | F9: =F8/6 -> 1575.5833 | H9: 101 | I9: 200 | J9: 2.35 | K9: 100 | L9: =K9*J9 -> 235 | N9: 601 | O9: 800 | P9: 9.45 | Q9: =if(($F$9-SUM(Q10:Q$13))-($O9-($N9-1))>0,($O9-($N9-1)),($F$9-SUM(Q10:Q$13))) -> 200 | R9: =Q9*P9 -> 1890 | T9: 601 | U9: 800 | V9: 9.45 | W9: =LET( remaining,$W$16-SUM(X10:X$13), result,IF(remaining<=X9,remaining/$V9,(U9-T9)+1), MAX(0,result) ) -> 200 | X9: =$V9*($U9-($T9-1)) -> 1890
H10: 0 | I10: 100 | J10: 0 | K10: 100 | L10: =K10*J10 -> 0 | N10: 501 | O10: 600 | P10: 8.4 | Q10: =if(($F$9-SUM(Q11:Q$13))-($O10-($N10-1))>0,($O10-($N10-1)),($F$9-SUM(Q11:Q$13))) -> 100 | R10: =Q10*P10 -> 840 | T10: 501 | U10: 600 | V10: 8.4 | W10: =LET( remaining,$W$16-SUM(X11:X$13), result,IF(remaining<=X10,remaining/$V10,(U10-T10)+1), MAX(0,result) ) -> 100 | X10: =$V10*($U10-($T10-1)) -> 840
N11: 401 | O11: 500 | P11: 6.3 | Q11: =if(($F$9-SUM(Q12:Q$13))-($O11-($N11-1))>0,($O11-($N11-1)),($F$9-SUM(Q12:Q$13))) -> 100 | R11: =Q11*P11 -> 630 | T11: 401 | U11: 500 | V11: 6.3 | W11: =LET( remaining,$W$16-SUM(X12:X$13), result,IF(remaining<=X11,remaining/$V11,(U11-T11)+1), MAX(0,result) ) -> 100 | X11: =$V11*($U11-($T11-1)) -> 630
B12: Bi Monthly Saving (Rs) | C12: =SUM(R7:R13) -> 13517.987 | E12: Tariff Escalation(%) | F12: 0.03 | N12: 101 | O12: 400 | P12: 4.7 | Q12: =if(($F$9-Q$13)-($O12-($N12-1))>0,($O12-($N12-1)),($F$9-SUM(Q12:Q$13))) -> 300 | R12: =Q12*P12 -> 1410 | T12: 101 | U12: 400 | V12: 4.7 | W12: =LET( remaining,$W$16-SUM(X13), result,IF(remaining<=X12,remaining/$V12,(U12-T12)+1), MAX(0,result) ) -> 300 | X12: =$V12*($U12-($T12-1)) -> 1410
B13: Annual Saving | C13: =(SUM(R7:R13)) * 6 -> 81107.925 | J13: Expected bill Rs. = | K13: =SUM(L7:L10) -> 1175 | N13: 0 | O13: 100 | P13: 0 | Q13: =if(($F$9-($O13-$N13))>0,($O13-$N13),($F$9-($O13-$N13))) -> 100 | R13: =Q13*P13 -> 0 | T13: 0 | U13: 100 | V13: 0 | W13: =LET( remaining,$W$16-SUM(X13), result,IF(remaining<=X13,$W$16,(U13-T13)), MAX(0,result) ) -> 100 | X13: =$V13*($U13-($T13-1)) -> 0
B14: Payback years | C14: =(C9/C13) -> 3.6701632 | D14: =INT(C14)&" years" -> 3 years | E14: =ROUNDUP((C14-INT(C14))*12,0)& " months" -> 9 months | J14: Slab cost per kW = | K14: =sum(J7:J10)/COUNT(J7:J10) -> 3.3375
B15: ROI % p.a. | C15: =(C13/C9)*100 -> 27.246745 | J15: Bill cost per kW = | K15: =K13/SUM(K7:K10) -> 2.9375
P16: Expected bill Rs. = | Q16: =SUM(R7:R13) -> 13517.987 | V16: Bill value Rs. = | W16: 32840
B17: Inverter cost = | C17: =Quotation!K5 -> 54799.92 | P17: Slab cost per kW = | Q17: =sum(P7:P13)/COUNT(P7:P13) -> 7.2714286 | V17: kWh consumed = | W17: =SUMIF(W7:W13,">0") -> 3248.4848
P18: Bill cost per kW = | Q18: =Q16/SUM(Q7:Q13) -> 8.5796716 | V18: Avg. cost per kW = | W18: =W16/W17 -> 10.109328
B23: IF NOT SOLAR | E23: Daily usage(KW) | F23: 25.9 | K23: FROM | L23: TO | M23: Rate | N23: kWh consumed | O23: Slab rate
E24: Annual Usage (KW) | F24: =F23*365 -> 9453.5 | K24: 1001 | L24: 9999 | M24: 11.55 | N24: =if(($F$25-SUM(N25:N$30))-($L24-$K24)>0,($L24-$K24),($F$25-SUM(N25:N$30))) -> 575.58333 | O24: =N24*M24 -> 6647.9875
E25: Bi Monthly Usage | F25: =F24/6 -> 1575.5833 | K25: 801 | L25: 1000 | M25: 10.5 | N25: =if(($F$25-($L25-$K25))>0,($L25-$K25)+1,($F$25-($L25-$K25))) -> 200 | O25: =N25*M25 -> 2100
K26: 601 | L26: 800 | M26: 9.45 | N26: =if(($F$25-($L26-$K26))>0,($L26-$K26)+1,($F$25-($L26-$K26))) -> 200 | O26: =N26*M26 -> 1890
K27: 501 | L27: 600 | M27: 8.4 | N27: =if(($F$25-($L27-$K27))>0,($L27-$K27)+1,($F$25-($L27-$K27))) -> 100 | O27: =N27*M27 -> 840
E28: Bi Monthly Expense | F28: =SUM(O24:O30) -> 13517.987 | K28: 401 | L28: 500 | M28: 6.3 | N28: =if(($F$25-($L28-$K28))>0,($L28-$K28)+1,($F$25-($L28-$K28))) -> 100 | O28: =N28*M28 -> 630
E29: Annual Expense | F29: =F28*6 -> 81107.925 | K29: 101 | L29: 400 | M29: 4.7 | N29: =if(($F$25-($L29-$K29))>0,($L29-$K29)+1,($F$25-($L29-$K29))) -> 300 | O29: =N29*M29 -> 1410
H30: RENTAL | K30: 0 | L30: 100 | M30: 0 | N30: =if(($F$25-($L30-$K30))>0,($L30-$K30),($F$25-($L30-$K30))) -> 100 | O30: =N30*M30 -> 0
E31: Payback period (years) | F31: {=INDEX(Table6[Years ],MATCH(TRUE,Table6[Break Even ]>=0,0)-1)+ABS(INDEX(Table6[Break Even ],MATCH(TRUE,Table6[Break Even ]>=0,0)-1))/(INDEX(Table6[Break Even ],MATCH(TRUE,Table6[Break Even ]>=0,0))-INDEX(Table6[Break Even ],MATCH(TRUE,Table6[Break Even ]>=0,0)-1))} -> 3.9588687 | H31: {=INDEX(Table6[Years ],MATCH(TRUE,Table6[Break Even (Rental)]>=0,0)-1)+ABS(INDEX(Table6[Break Even (Rental)],MATCH(TRUE,Table6[Break Even (Rental)]>=0,0)-1))/(INDEX(Table6[Break Even (Rental)],MATCH(TRUE,Table6[Break Even (Rental)]>=0,0))-INDEX(Table6[Break Even (Rental)],MATCH(TRUE,Table6[Break Even (Rental)]>=0,0)-1))} -> 1.3065555
E32: (years, months) | F32: =INT(F31)&" years" -> 3 years | G32: =ROUNDUP((F31-INT(F31))*12,0)& " months" -> 12 months | H32: =INT(H31)&" years" -> 1 years | I32: =ROUNDUP((H31-INT(H31))*12,0)& " months" -> 4 months
F34: Tarif increase = | G34: 0.02
E36: Years | F36: Yearly Bill without solar (with tarif increase) | G36: Yearly Bill with solar | H36: Bi-monthyl bill without solar | I36: Bi-monthyl bill with solar | J36: Yearly savings | K36: Costs without solar (accumulated) | L36: Cost of going solar (accumulated) | M36: Break Even | N36: Yearly savings (Rental) | O36: Break Even (Rental) | Q36: Rs. per unit (for tenant) = | S36: 8
E37: 1 | F37: =F29 -> 81107.925 | G37: =0.1*F37 -> 8110.7925 | H37: =F37/6 -> 13517.987 | I37: =G37/6 -> 1351.7987 | J37: =F37-G37 -> 72997.133 | K37: =F37 -> 81107.925 | L37: =C9+G37 -> 305790.11 | M37: =-C9+J37 -> -224682.19 | N37: =J37+'On-grid System sizing calculato'!$L$17 -> #DIV/0! | O37: =-C9-G37+'On-grid System sizing calculato'!I17+S38 -> -69806.074 | Q37: Units consumed (yearly) = | S37: =Energy_Usage_kWh[[#TOTALS],[(2025-2026) kWh]] -> 19486.53
E38: 2 | F38: =F37*(1+$G$34) -> 82730.083 | G38: =0.1*F38 -> 8273.0084 | H38: =F38/6 -> 13788.347 | I38: =G38/6 -> 1378.8347 | J38: =F38-G38 -> 74457.075 | K38: =K37+F38 -> 163838.01 | L38: =L37+G38 -> 314063.12 | M38: =M37+J38 -> -150225.11 | N38: =J38+'On-grid System sizing calculato'!$L$17 -> #DIV/0! | O38: =O37-G38+'On-grid System sizing calculato'!I17+$S$38 -> 157904.96 | Q38: Estimated bill for tenant (yearly) = | S38: =S37*S36 -> 155892.24
E39: 3 | F39: =F38*(1+$G$34) -> 84384.685 | G39: =0.1*F39 -> 8438.4685 | H39: =F39/6 -> 14064.114 | I39: =G39/6 -> 1406.4114 | J39: =F39-G39 -> 75946.217 | K39: =K38+F39 -> 248222.69 | L39: =L38+G39 -> 322501.59 | M39: =M38+J39 -> -74278.897 | N39: =J39+'On-grid System sizing calculato'!$L$17 -> #DIV/0! | O39: =O38-G39+'On-grid System sizing calculato'!I27+$S$38 -> 305358.73 | Q39: Estimated bill for renter (yearly) = | S39: =G37 -> 8110.7925
E40: 4 | F40: =F39*(1+$G$34) -> 86072.379 | G40: =0.1*F40 -> 8607.2379 | H40: =F40/6 -> 14345.396 | I40: =G40/6 -> 1434.5396 | J40: =F40-G40 -> 77465.141 | K40: =K39+F40 -> 334295.07 | L40: =L39+G40 -> 331108.83 | M40: =M39+J40 -> 3186.2438 | N40: =J40+'On-grid System sizing calculato'!$L$17 -> #DIV/0! | O40: =O39-G40+#REF!+$S$38 -> #REF!
E41: 5 | F41: =F40*(1+$G$34) -> 87793.826 | G41: =0.1*F41 -> 8779.3826 | H41: =F41/6 -> 14632.304 | I41: =G41/6 -> 1463.2304 | J41: =F41-G41 -> 79014.444 | K41: =K40+F41 -> 422088.9 | L41: =L40+G41 -> 339888.21 | M41: =M40+J41 -> 82200.688 | N41: =J41+'On-grid System sizing calculato'!$L$17 -> #DIV/0! | O41: =O40-G41+#REF!+$S$38 -> #REF!
E42: 6 | F42: =F41*(1+$G$34) -> 89549.703 | G42: =0.1*F42 -> 8954.9703 | H42: =F42/6 -> 14924.951 | I42: =G42/6 -> 1492.495 | J42: =F42-G42 -> 80594.733 | K42: =K41+F42 -> 511638.6 | L42: =L41+G42 -> 348843.18 | M42: =M41+J42 -> 162795.42 | N42: =J42+'On-grid System sizing calculato'!$L$17 -> #DIV/0! | O42: =O41-G42+#REF!+$S$38 -> #REF!
E43: 7 | F43: =F42*(1+$G$34) -> 91340.697 | G43: =0.1*F43 -> 9134.0697 | H43: =F43/6 -> 15223.45 | I43: =G43/6 -> 1522.345 | J43: =F43-G43 -> 82206.627 | K43: =K42+F43 -> 602979.3 | L43: =L42+G43 -> 357977.25 | M43: =M42+J43 -> 245002.05 | N43: =J43+'On-grid System sizing calculato'!$L$17 -> #DIV/0! | O43: =O42-G43+#REF!+$S$38 -> #REF!
E44: 8 | F44: =F43*(1+$G$34) -> 93167.511 | G44: =0.1*F44 -> 9316.7511 | H44: =F44/6 -> 15527.918 | I44: =G44/6 -> 1552.7919 | J44: =F44-G44 -> 83850.76 | K44: =K43+F44 -> 696146.81 | L44: =L43+G44 -> 367294 | M44: =M43+J44 -> 328852.81 | N44: =J44+'On-grid System sizing calculato'!$L$17 -> #DIV/0! | O44: =O43-G44+#REF!+$S$38 -> #REF!
E45: 9 | F45: =F44*(1+$G$34) -> 95030.861 | G45: =0.1*F45 -> 9503.0861 | H45: =F45/6 -> 15838.477 | I45: =G45/6 -> 1583.8477 | J45: =F45-G45 -> 85527.775 | K45: =K44+F45 -> 791177.67 | L45: =L44+G45 -> 376797.09 | M45: =M44+J45 -> 414380.58 | N45: =J45+'On-grid System sizing calculato'!$L$17 -> #DIV/0! | O45: =O44-G45+#REF!+$S$38 -> #REF!
E46: 10 | F46: =F45*(1+$G$34) -> 96931.478 | G46: =0.1*F46 -> 9693.1478 | H46: =F46/6 -> 16155.246 | I46: =G46/6 -> 1615.5246 | J46: =F46-G46 -> 87238.331 | K46: =K45+F46 -> 888109.15 | L46: =L45+G46 -> 386490.24 | M46: =M45+J46 -> 501618.91 | N46: =J46+'On-grid System sizing calculato'!$L$17 -> #DIV/0! | O46: =O45-G46+#REF!+$S$38 -> #REF!
E47: 11 | F47: =F46*(1+$G$34) -> 98870.108 | G47: =0.1*F47 -> 9887.0108 | H47: =F47/6 -> 16478.351 | I47: =G47/6 -> 1647.8351 | J47: =F47-G47 -> 88983.097 | K47: =K46+F47 -> 986979.26 | L47: =L46+G47+C17 -> 451177.17 | M47: =M46+J47-C17 -> 535802.09 | N47: =J47+'On-grid System sizing calculato'!$L$17 -> #DIV/0! | O47: =O46-G47+#REF!+$S$38 -> #REF!
E48: 12 | F48: =F47*(1+$G$34) -> 100847.51 | G48: =0.1*F48 -> 10084.751 | H48: =F48/6 -> 16807.918 | I48: =G48/6 -> 1680.7918 | J48: =F48-G48 -> 90762.759 | K48: =K47+F48 -> 1087826.8 | L48: =L47+G48 -> 461261.92 | M48: =M47+J48 -> 626564.85 | N48: =J48+'On-grid System sizing calculato'!$L$17 -> #DIV/0! | O48: =O47-G48+#REF!+$S$38 -> #REF!
E49: 13 | F49: =F48*(1+$G$34) -> 102864.46 | G49: =0.11*F49 -> 11315.091 | H49: =F49/6 -> 17144.077 | I49: =G49/6 -> 1885.8484 | J49: =F49-G49 -> 91549.37 | K49: =K48+F49 -> 1190691.2 | L49: =L48+G49 -> 472577.01 | M49: =M48+J49 -> 718114.22 | N49: =J49+'On-grid System sizing calculato'!$L$17 -> #DIV/0! | O49: =O48-G49+#REF!+$S$38 -> #REF!
...

Sheet Quotation
B1: System size = | C1: 6000
B2: Items | D2: Total unit | E2: UoM | F2: Price per unit | G2: BoM Cost | H2: Margin | I2: Basic Cost | J2: GST % | K2: Final Cost | M2: Cost per panel | N2: Difference
A3: Adani | B3: Panels TOPCon DCR | C3: 615 | D3: 11 | E3: nos | F3: 26 | G3: =D3*F3*C3 -> 175890 | H3: =G3*0.2 -> 35178 | I3: =G3+H3 -> 211068 | J3: 0.05 | K3: =I3*1.05 -> 221621.4 | L3: =K3/$K$16 -> 0.58255166 | M3: =K3/D3 -> 20147.4 | N3: =M3-M4 -> 7522.9875
A4: Renesys | B4: Panels TOPCon non-DCR | C4: 615 | D4: 11 | E4: nos | F4: 17 | G4: =D4*F4*C4 -> 115005 | H4: =G4*0.15 -> 17250.75 | I4: =G4+H4 -> 132255.75 | J4: 0.05 | K4: =I4*1.05 -> 138868.54 | L4: =K4/K18 -> 0.46650381 | M4: =K4/D4 -> 12624.413
A5: Deye | B5: Inverter (On-Grid) | C5: 12kW (3 ph) | D5: 1 | E5: nos | F5: 43492 | G5: =D5*F5 -> 43492 | H5: =G5*0.2 -> 8698.4 | I5: =G5+H5 -> 52190.4 | J5: 0.05 | K5: =I5*1.05 -> 54799.92 | L5: =K5/$K$16 -> 0.14404649
B6: DCDB | D6: 1 | E6: nos | F6: 4950 | G6: =F6*D6 -> 4950 | H6: =G6*0.2 -> 990 | I6: =G6+H6 -> 5940 | J6: 0.18 | K6: =I6*1.18 -> 7009.2 | L6: =K6/$K$16 -> 0.018424309
B7: ACDB | D7: 1 | E7: nos | F7: 4250 | G7: =F7*D7 -> 4250 | H7: =G7*0.2 -> 850 | I7: =G7+H7 -> 5100 | J7: 0.18 | K7: =I7*1.18 -> 6018 | L7: =K7/$K$16 -> 0.015818851
B8: Mounting structure | D8: LS | E8: LS | F8: 4000 | G8: =F8*(C1/1000) -> 24000 | H8: =G8*0.2 -> 4800 | I8: =G8+H8 -> 28800 | J8: 0.18 | K8: =I8*1.18 -> 33984 | L8: =K8/$K$16 -> 0.089329982
B9: Earthing rod | C9: 2m, dia? | D9: 3 | E9: nos | F9: 3500 | G9: =F9 -> 3500 | H9: =G9*0.2 -> 700 | I9: =G9+H9 -> 4200 | J9: 0.18 | K9: =I9*1.18 -> 4956 | L9: =K9/$K$16 -> 0.013027289
B10: Lightning arrestor | C10: 1m, dia? | D10: 1 | E10: nos | G10: 0 | H10: =G10*0.15 -> 0 | I10: =G10+H10 -> 0 | J10: 0.18 | K10: =I10*1.18 -> 0 | L10: =K10/$K$16 -> 0
B11: MC4 connectors | D11: 12 | E11: nos | F11: 42 | G11: =D11*F11 -> 504 | H11: =G11*0.2 -> 100.8 | I11: =G11+H11 -> 604.8 | J11: 0.18 | K11: =I11*1.18 -> 713.664 | L11: =K11/$K$16 -> 0.0018759296
B12: Pins & other accessories | D12: LS | E12: LS | G12: 4000 | H12: =G12*0.25 -> 1000 | I12: =G12+H12 -> 5000 | J12: 0.18 | K12: =I12*1.18 -> 5900 | L12: =K12/$K$16 -> 0.015508677
B13: Design / Installation / Logistics | D13: LS | E13: LS | F13: 3000 | G13: =F13*(C1/1000) -> 18000 | H13: =G13*0.25 -> 4500 | I13: =G13+H13 -> 22500 | J13: 0.18 | K13: =I13*1.18 -> 26550 | L13: =K13/$K$16 -> 0.069789048
A14: 360watts | B14: IoT hub for energy automation | D14: 1 | E14: nos | F14: 5000 | G14: =F14*D14 -> 5000 | H14: =G14*1 -> 5000 | I14: =G14+H14 -> 10000 | J14: 0.18 | K14: =I14*1.18 -> 11800 | L14: =K14/$K$16 -> 0.031017355
B15: Wiring | F15: 5000 | G15: =F15 -> 5000 | H15: =G15*0.2 -> 1000 | I15: =G15+H15 -> 6000 | J15: 0.18 | K15: =I15*1.18 -> 7080 | L15: =K15/$K$16 -> 0.018610413
K16: =SUM(K3,K5:K15) -> 380432.18 | L16: =(K16/C1)&" / kW)" -> 63.405364 / kW)
B17: Subsidy PM Surya Ghar | D17: =C1/1000 -> 6 | F17: 30000 | G17: =SUM(G3,G5:G15) -> 288586 | H17: =SUM(H3,H5:H15) -> 62817.2 | J17: =H17/K17 -> 0.20770673 | K17: =K16-(if((F17*D17)>78000,78000,(F17*D17))) -> 302432.18 | L17: =(K17/C1)&" / kW)" -> 50.405364 / kW) | N17: DCR
G18: =SUM(G4:G15) -> 227701 | H18: =SUM(H4:H14) -> 43889.95 | J18: =H18/K18 -> 0.14744037 | K18: =SUM(K4:K15) -> 297679.32 | L18: =K18/(C1)&" / kW)" -> 49.61322025 / kW) | N18: non-DCR | O18: ="Rs. "&Round(K18*0.15,0) -> Rs. 44652
B19: ADDITIONAL COST: | D19: meter | E19: cost | F19: wiring total cost | K19: =MINUS(K17,K18) -> 4752.8625 | L19: Difference
B20: DC cable (Panels to DCDB/Inverter) | C20: 6 sq. mm
B21: AC cable (Inverter to ACDB) | C21: 6 sq. mm 4-core
B22: AC cable | C22: 4 sq mm | E22: ~60/m
B23: Earthing cable | C23: DC (6 sq. mm) | E23: ~66/m
C24: DC (10 sq. mm) | E24: ~139/m
C25: AC (6 sq. mm) | E25: ~100/m
C26: AC (10 sq. mm) | E26: ~150/m
B27: TOTAL
B30: QUOTATION
C32: MATTERLESS TECHNOLOGIES OPC PRIVATE LIMITED FORGE FACTORY, KCT TECHPARK, 03 ATHIPALAYAM ROAD, COIMBATORE - 641049 GST: 33AATCM6353J1ZZ PH: 9087610051
H37: =2899/1.18 -> 2456.7797
B39: To | F39: 14.03.2026
B40: Shakthi Electricals
B41: Avinashi
B44: Items | C44: Details | D44: Basic Cost | E44: GST % | F44: Final Cost
B45: Panels (Adani TOPCon / 9 panels) | C45: 615Wp | D45: 142065 | E45: 0.05 | F45: 149168.25
B46: Inverter (1-ph On-Grid) | C46: 5kW (1P) | D46: 32830 | E46: 0.05 | F46: 34471.5
B47: DCDB | C47: 1 nos | D47: 5750 | E47: 0.18 | F47: 6785
B48: ACDB | C48: 1 nos | D48: 12650 | E48: 0.18 | F48: 14927
B49: Mounting structure (GI) | C49: LS | D49: 29610 | E49: 0.18 | F49: 34939.8
B50: Earthing rod | C50: 3 nos | D50: 2760 | E50: 0.18 | F50: 3256.8
...

Sheet On-grid System sizing calculato
F2: EB | G2: SOLAR | K2: To bill Rs. / kWh = | L2: 8
A3: Irradiance | B3: Months | C3: (2025-2026) kWh | D3: (2025-2026) Bill | E3: 2024-2025 | F3: Avg Rs. /kWh | G3: Daily kWh | H3: 2m kWh | I3: net import | J3: Avg Rs. /kWh | K3: To bill | L3: Savings | N3: Parameters | O3: Normal System | P3: Future expansion | Q3: EV alone | R3: units
B4: May | C4: =2053.88+1323.65 -> 3377.53 | D4: =19042.31+10608.16 -> 29650.47 | H4: =G6*60 -> 3240 | I4: =(H4-C5)*6.7 -> 21708 | J4: =('Return of investment '!$L$56/(15*6))/H4 -> 2.0239965 | K4: =C5*$L$2 -> 0 | L4: =K4-(J4*H4) -> -6557.7485 | N4: Daily Consumption (AC) | O4: 8.5 | P4: 8 | Q4: =F33+I33 -> 17.357143 | R4: kWh
B5: April | E5: 749.11 | N5: Energy Needed (AC) | O5: =O4/C33 -> 8.5 | P5: =P4/C33 -> 8 | Q5: =Q4/C33 -> 17.357143 | R5: kWh
B6: March | C6: =1815.58+1253.71 -> 3069.29 | D6: =16289.95+9800.35 -> 26090.3 | F6: =D6/C6 -> 8.500435 | G6: =$O$27*4.5 -> 54 | H6: =G8*60 -> 2880 | I6: =(H6-C7)*6.7 -> 19296 | J6: =('Return of investment '!$L$56/(15*6))/H6 -> 2.276996 | K6: =C7*$L$2 -> 0 | L6: =K6-(J6*H6) -> -6557.7485 | N6: Desired AC output (from inverter) | O6: =O5/(C30*C33) -> 1.8888889 | P6: =P5/(C30*C33) -> 1.7777778 | Q6: =Q5/(C30*C33) -> 3.8571429 | R6: kW
B7: February | E7: 416.2 | N7: Power Factor (PF) | O7: 1 | P7: 1 | Q7: 1
B8: January | C8: =1458.42+882.29 -> 2340.71 | D8: =12164.75+5634.05 -> 17798.8 | F8: =D8/C8 -> 7.6040176 | G8: =$O$27*4 -> 48 | H8: =G10*60 -> 2880 | I8: =(H8-C9)*6.7 -> 19296 | J8: =('Return of investment '!$L$56/(15*6))/H8 -> 2.276996 | K8: =C9*$L$2 -> 0 | L8: =K8-(J8*H8) -> -6557.7485 | N8: Required AC output (from inverter) | O8: =O6/O7 -> 1.8888889 | P8: =P6/P7 -> 1.7777778 | Q8: =Q6/Q7 -> 3.8571429 | R8: kVA | S8: Reactive power (kVA) (i.e. useful energy) = Desired AC output / PF
B9: December | E9: 399 | N9: Corresponding DC sizing | O9: =1.1*O8 -> 2.0777778 | P9: =1.25*P8 -> 2.2222222 | Q9: =1.25*Q8 -> 4.8214286 | R9: kW | S9: DC/AC ratio = 1.25
B10: November | C10: =4449+887 -> 5336 | D10: =46705.95+5683.5 -> 52389.45 | F10: =D10/C10 -> 9.8181128 | G10: =$O$27*4 -> 48 | H10: =G12*60 -> 2880 | I10: =(H10-C11)*6.7 -> 495.8 | J10: =('Return of investment '!$L$56/(15*6))/H10 -> 2.276996 | K10: =C11*$L$2 -> 22448 | L10: =K10-(J10*H10) -> 15890.251
B11: October | C11: =285+1412+1109 -> 2806 | D11: =11628.6+8128.95+634.5 -> 20392.05 | E11: 415.02 | F11: =D11/C11 -> 7.2673022
B12: September | G12: =$O$27*4 -> 48 | H12: =G14*60 -> 2880 | I12: =(H12-C13)*6.7 -> 19296 | J12: =('Return of investment '!$L$56/(15*6))/H12 -> 2.276996 | K12: =C13*$L$2 -> 0 | L12: =K12-(J12*H12) -> -6557.7485
B13: August | E13: 405.58
B14: July | G14: =$O$27*4 -> 48 | H14: =G16*60 -> 0 | I14: =(H14-C15)*6.7 -> 0 | J14: =('Return of investment '!$L$56/(15*6))/H14 -> #DIV/0! | K14: =C15*$L$2 -> 0 | L14: =K14-(J14*H14) -> #DIV/0! | N14: Panels Age(Years) | O14: Expected Output N.S (KWh) | P14: Expected Output with EV (KWh)
B15: June | E15: 705.4 | N15: 10 | O15: =O8*(1-0.005)^10 -> 1.7965414 | P15: =Q8*(1-0.005)^10 -> 3.6685676
B16: May | C16: =1600+957 -> 2557 | D16: =13800+6418.5 -> 20218.5 | N16: 15 | O16: =O8*(1-0.005)^15 -> 1.7520747 | P16: =Q8*(1-0.005)^15 -> 3.577766
C17: =SUM(Energy_Usage_kWh[(2025-2026) kWh]) -> 19486.53 | D17: =SUM(Energy_Usage_kWh[(2025-2026) Bill]) -> 166539.57 | E17: =SUM(Energy_Usage_kWh[2024-2025]) -> 3090.31 | H17: =SUM(H4:H15) -> 14760 | I17: =SUM(I4:I15) -> 80091.8 | J17: =AVERAGE(J4:J15) -> #DIV/0! | K17: =SUM(K4:K16) -> 22448 | L17: =SUM(L4:L16) -> #DIV/0! | N17: 20 | O17: =O8*(1-0.005)^20 -> 1.7087087 | P17: =Q8*(1-0.005)^20 -> 3.4892119
B18: Daily consumption (kWh) = | C18: =Energy_Usage_kWh[[#TOTALS],[(2025-2026) kWh]]/365 -> 53.387753 | D18: ="Rs. "&round(SUM(Energy_Usage_kWh[(2025-2026) Bill])/Energy_Usage_kWh[[#TOTALS],[(2025-2026) kWh]], 2) -> Rs. 8.55 | E18: =Energy_Usage_kWh[[#TOTALS],[2024-2025]]/365 -> 8.4666027 | F18: =AVERAGE(F5:F15) -> 8.2974669 | G18: =AVERAGE(G6:G16) -> 49.2
B20: QUESTIONS: 1. Do you install new AC in the Mar/Apr 2025? --> due to observed additional 300-600 units bi-monthly since last 6 bills | E20: FUTURE PLANS: 1. Plans to purchase EV car in next 12 to 24 months? 2. New appliances in next 12 months? Eg. Dishwasher, AC, etc.
O24: w/o EV | Q24: with EV
N25: Panel Wp | O25: 620 | P25: 610 | Q25: 615
N26: No of panels | O26: =ROUND((((System_Size[[#TOTALS],[Normal System]])*1000)/P25),0) -> 3 | P26: =ROUND((((System_Size[[#TOTALS],[Normal System]]+System_Size[[#TOTALS],[Future expansion]])*1000)/P25),0) -> 7 | Q26: 11
N27: Available inverter size (kW) | O27: 12 | P27: 8 | Q27: 6
N28: Actual DC sizing (kW) | O28: =(O26*O25)/1000 -> 1.86 | P28: =(P26*P25)/1000 -> 4.27 | Q28: =(Q26*Q25)/1000 -> 6.765
B29: Data needed | C29: Column 1 | E29: Months | F29: Energy usage (units) | H29: Months | I29: Energy usage (units) | N29: Actual DC/AC ratio | O29: =O28/O27 -> 0.155 | P29: =P28/P27 -> 0.53375 | Q29: =Q28/(O8+Q8) -> 1.1773343
B30: Average peak sun hour | C30: 4.5 | E30: EV Brand name | F30: TATA Nexon | H30: EV Brand name
B31: Total system losses (%) | C31: 25 | E31: Battery Capacity | F31: 45 | H31: Battery Capacity Battery Capacity | I31: 0
B32: Derate factor (%) | C32: 0 | E32: Full charging times per week | F32: 3 | H32: Full charging times per week | I32: 4
B33: Performance ratio | C33: =1-(C32/100) -> 1 | E33: Extra power needed(KWh) per day | F33: =(F31*0.9*F32)/7 -> 17.357143 | H33: Extra power needed(KWh) per day | I33: =(I31*0.9*I32)/7 -> 0

Sheet Commercial RoI 
B3: System Size(KW) | C3: 25
H5: Slab Consumption < 500 kWh | N5: Slab Consumption > 500 kWh | T5: Slab Consumption > 500 kWh
H6: FROM | I6: TO | J6: Rate | K6: kWh consumed | L6: Slab rate | N6: FROM | O6: TO | P6: Rate | Q6: kWh consumed | R6: Slab rate | T6: FROM | U6: TO | V6: Rate | W6: kWh consumed | X6: Slab rate
B7: System cost | C7: 2100000 | E7: Daily generation(KW) | F7: 80 | H7: 401 | I7: 500 | J7: 6.3 | L7: =K7*J7 -> 0 | N7: 1001 | O7: 9999 | P7: 11.55 | Q7: =if(($F$9-SUM(Q8:Q$13))-($O7-($N7-1))>0,($O7-($N7-1)),($F$9-SUM(Q8:Q$13))) -> 3866.6667 | R7: =Q7*P7 -> 44660 | T7: 1001 | U7: 9999 | V7: 11.55 | W7: =LET( remaining,$W$16-SUM(X8:X14), result,IF(remaining<=X7,remaining/$V7,(U7-T7)+1), MAX(0,result) ) -> 3754.5455 | X7: =$V7*($U7-($T7-1)) -> 103938.45
B8: Fixed cost | E8: Annual Generation (KW) | F8: =F7*365 -> 29200 | H8: 201 | I8: 400 | J8: 4.7 | L8: =K8*J8 -> 0 | N8: 801 | O8: 1000 | P8: 10.5 | Q8: =if(($F$9-SUM(Q9:Q$13))-($O8-($N8-1))>0,($O8-($N8-1)),($F$9-SUM(Q9:Q$13))) -> 200 | R8: =Q8*P8 -> 2100 | T8: 801 | U8: 1000 | V8: 10.5 | W8: =LET( remaining,$W$16-SUM(X9:X$14), result,IF(remaining<=X8,remaining/$V8,(U8-T8)+1), MAX(0,result) ) -> 200 | X8: =$V8*($U8-($T8-1)) -> 2100
B9: Net Investment | C9: =C7+C8 -> 2100000 | E9: Bi Monthly Generation | F9: =F8/6 -> 4866.6667 | H9: 101 | I9: 200 | J9: 2.35 | L9: =K9*J9 -> 0 | N9: 601 | O9: 800 | P9: 9.45 | Q9: =if(($F$9-SUM(Q10:Q$13))-($O9-($N9-1))>0,($O9-($N9-1)),($F$9-SUM(Q10:Q$13))) -> 200 | R9: =Q9*P9 -> 1890 | T9: 601 | U9: 800 | V9: 9.45 | W9: =LET( remaining,$W$16-SUM(X10:X$14), result,IF(remaining<=X9,remaining/$V9,(U9-T9)+1), MAX(0,result) ) -> 200 | X9: =$V9*($U9-($T9-1)) -> 1890
H10: 0 | I10: 100 | J10: 0 | L10: =K10*J10 -> 0 | N10: 501 | O10: 600 | P10: 8.4 | Q10: =if(($F$9-SUM(Q11:Q$13))-($O10-($N10-1))>0,($O10-($N10-1)),($F$9-SUM(Q11:Q$13))) -> 100 | R10: =Q10*P10 -> 840 | T10: 501 | U10: 600 | V10: 8.4 | W10: =LET( remaining,$W$16-SUM(X11:X$14), result,IF(remaining<=X10,remaining/$V10,(U10-T10)+1), MAX(0,result) ) -> 100 | X10: =$V10*($U10-($T10-1)) -> 840
N11: 401 | O11: 500 | P11: 6.3 | Q11: =if(($F$9-SUM(Q12:Q$13))-($O11-($N11-1))>0,($O11-($N11-1)),($F$9-SUM(Q12:Q$13))) -> 100 | R11: =Q11*P11 -> 630 | T11: 401 | U11: 500 | V11: 6.3 | W11: =LET( remaining,$W$16-SUM(X12:X$14), result,IF(remaining<=X11,remaining/$V11,(U11-T11)+1), MAX(0,result) ) -> 100 | X11: =$V11*($U11-($T11-1)) -> 630
B12: Bi Monthly Saving (Rs) | C12: =SUM(R7:R13) -> 51530 | E12: Tariff Escalation(%) | F12: 0.03 | N12: 101 | O12: 400 | P12: 4.7 | Q12: =if(($F$9-Q$13)-($O12-($N12-1))>0,($O12-($N12-1)),($F$9-SUM(Q12:Q$13))) -> 300 | R12: =Q12*P12 -> 1410 | T12: 201 | U12: 400 | V12: 4.7 | W12: =LET( remaining,$W$16-SUM(X13:X$14), result,IF(remaining<=X12,remaining/$V12,(U12-T12)+1), MAX(0,result) ) -> 200 | X12: =$V12*($U12-($T12-1)) -> 940
B13: Annual Saving | C13: =(SUM(R7:R13)) * 6 -> 309180 | J13: Expected bill Rs. = | K13: =SUM(L7:L10) -> 0 | N13: 0 | O13: 100 | P13: 0 | Q13: =if(($F$9-($O13-$N13))>0,($O13-$N13),($F$9-($O13-$N13))) -> 100 | R13: =Q13*P13 -> 0 | T13: 101 | U13: 200 | V13: 2.35 | W13: =LET( remaining,$W$16-SUM(X14:X$14), result,IF(remaining<=X13,remaining/$V13,(U13-T13)+1), MAX(0,result) ) -> 100 | X13: =$V13*($U13-($T13-1)) -> 235
B14: Payback years | C14: =(C9/C13) -> 6.7921599 | D14: =INT(C14)&" years" -> 6 years | E14: =ROUNDUP((C14-INT(C14))*12,0)& " months" -> 10 months | J14: Slab cost per kW = | K14: =sum(J7:J10)/COUNT(J7:J10) -> 3.3375 | T14: 0 | U14: 100 | V14: 0 | W14: =LET( remaining,$W$16-SUM(X14:X$15), result,IF(remaining<=X14,remaining/$V14,(U14-T14)), MAX(0,result) ) -> 100 | X14: =$V14*($U14-($T14-1)) -> 0
B15: ROI % p.a. | C15: =(C13/C9)*100 -> 14.722857 | J15: Bill cost per kW = | K15: =K13/SUM(K7:K10) -> #DIV/0!
P16: Expected bill Rs. = | Q16: =SUM(R7:R13) -> 51530 | V16: Bill value Rs. = | W16: 50000
B17: Inverter cost = | C17: =Quotation!K5 -> 54799.92 | P17: Slab cost per kW = | Q17: =sum(P7:P13)/COUNT(P7:P13) -> 7.2714286 | V17: kWh consumed = | W17: =SUMIF(W7:W14,">0") -> 4754.5455
P18: Bill cost per kW = | Q18: =Q16/SUM(Q7:Q13) -> 10.588356 | V18: Avg. cost per kW = | W18: =W16/W17 -> 10.516252
B23: IF NOT SOLAR | E23: Daily usage(KW) | F23: 8 | K23: FROM | L23: TO | M23: Rate | N23: kWh consumed | O23: Slab rate
E24: Annual Usage (KW) | F24: =F23*365 -> 2920 | K24: 1001 | L24: 9999 | M24: 11.55 | N24: =if(($F$25-SUM(N25:N$31))-($L24-$K24)>0,($L24-$K24),($F$25-SUM(N25:N$31))) -> 0 | O24: =N24*M24 -> 0
E25: Bi Monthly Usage | F25: =F24/6 -> 486.66667 | K25: 801 | L25: 1000 | M25: 10.5 | N25: =if(($F$25-SUM(N26:N$31))-($L25-$K25)>0,($L25-$K25),($F$25-SUM(N26:N$31))) -> 0 | O25: =N25*M25 -> 0
K26: 601 | L26: 800 | M26: 9.45 | N26: =if(($F$25-SUM(N27:N$31))-($L26-$K26)>0,($L26-$K26),($F$25-SUM(N27:N$31))) -> 0 | O26: =N26*M26 -> 0
K27: 501 | L27: 600 | M27: 8.4 | N27: =if(($F$25-SUM(N28:N$31))-($L27-$K27)>0,($L27-$K27),($F$25-SUM(N28:N$31))) -> 0 | O27: =N27*M27 -> 0
E28: Bi Monthly Expense | F28: =SUM(O24:O31) -> 1732.85 | K28: 401 | L28: 500 | M28: 6.3 | N28: =if(($F$25-SUM(N29:N$31))-($L28-$K28)>0,($L28-$K28),($F$25-SUM(N29:N$31))) -> 89.666667 | O28: =N28*M28 -> 564.9
E29: Annual Expense | F29: =F28*6 -> 10397.1 | K29: 201 | L29: 400 | M29: 4.7 | N29: =if(($F$25-SUM(N30:N$31))-($L29-$K29)>0,($L29-$K29),($F$25-SUM(N30:N$31))) -> 199 | O29: =N29*M29 -> 935.3
H30: RENTAL | K30: 101 | L30: 200 | M30: 2.35 | N30: =if(($F$25-SUM(N31:N$31))-($L30-$K30)>0,($L30-$K30),($F$25-SUM(N31:N$31))) -> 99 | O30: =N30*M30 -> 232.65
E31: Payback period (years) | F31: {=INDEX(Table6_2[Years ],MATCH(TRUE,Table6_2[Break Even ]>=0,0)-1)+ABS(INDEX(Table6_2[Break Even ],MATCH(TRUE,Table6_2[Break Even ]>=0,0)-1))/(INDEX(Table6_2[Break Even ],MATCH(TRUE,Table6_2[Break Even ]>=0,0))-INDEX(Table6_2[Break Even ],MATCH(TRUE,Table6_2[Break Even ]>=0,0)-1))} -> #N/A | H31: {=INDEX(Table6_2[Years ],MATCH(TRUE,Table6_2[Break Even (Rental)]>=0,0)-1)+ABS(INDEX(Table6_2[Break Even (Rental)],MATCH(TRUE,Table6_2[Break Even (Rental)]>=0,0)-1))/(INDEX(Table6_2[Break Even (Rental)],MATCH(TRUE,Table6_2[Break Even (Rental)]>=0,0))-INDEX(Table6_2[Break Even (Rental)],MATCH(TRUE,Table6_2[Break Even (Rental)]>=0,0)-1))} -> #N/A | K31: 0 | L31: 100 | M31: 0 | N31: =if(($F$25-($L30-$K30))>0,($L30-$K30),($F$25-($L30-$K30))) -> 99 | O31: =N31*M31 -> 0
E32: (years, months) | F32: =INT(F31)&" years" -> #N/A | G32: =ROUNDUP((F31-INT(F31))*12,0)& " months" -> #N/A | H32: =INT(H31)&" years" -> #N/A | I32: =ROUNDUP((H31-INT(H31))*12,0)& " months" -> #N/A
F34: Tarif increase = | G34: 0.03
E36: Years | F36: Yearly Bill without solar (with tarif increase) | G36: Yearly Bill with solar | H36: Bi-monthyl bill without solar | I36: Bi-monthyl bill with solar | J36: Yearly savings | K36: Costs without solar (accumulated) | L36: Cost of going solar (accumulated) | M36: Break Even | N36: Yearly savings (Rental) | O36: Break Even (Rental) | Q36: Rs. per unit (for tenant) = | S36: 8
E37: 1 | F37: =F29 -> 10397.1 | G37: =0.1*F37 -> 1039.71 | H37: =F37/6 -> 1732.85 | I37: =G37/6 -> 173.285 | J37: =F37-G37 -> 9357.39 | K37: =F37 -> 10397.1 | L37: =C9+G37 -> 2101039.7 | M37: =-C9+J37 -> -2090642.6 | N37: =J37+'On-grid System sizing calculato'!$L$17 -> #DIV/0! | O37: =-C9-G37+'On-grid System sizing calculato'!I17+S38 -> -1865055.7 | Q37: Units consumed (yearly) = | S37: =Energy_Usage_kWh[[#TOTALS],[(2025-2026) kWh]] -> 19486.53
E38: 2 | F38: =F37*(1+$G$34) -> 10709.013 | G38: =0.1*F38 -> 1070.9013 | H38: =F38/6 -> 1784.8355 | I38: =G38/6 -> 178.48355 | J38: =F38-G38 -> 9638.1117 | K38: =K37+F38 -> 21106.113 | L38: =L37+G38 -> 2102110.6 | M38: =M37+J38 -> -2081004.5 | N38: =J38+'On-grid System sizing calculato'!$L$17 -> #DIV/0! | O38: =O37-G38+'On-grid System sizing calculato'!I17+$S$38 -> -1630142.5 | Q38: Estimated bill for tenant (yearly) = | S38: =S37*S36 -> 155892.24
E39: 3 | F39: =F38*(1+$G$34) -> 11030.283 | G39: =0.1*F39 -> 1103.0283 | H39: =F39/6 -> 1838.3806 | I39: =G39/6 -> 183.83806 | J39: =F39-G39 -> 9927.2551 | K39: =K38+F39 -> 32136.396 | L39: =L38+G39 -> 2103213.6 | M39: =M38+J39 -> -2071077.2 | N39: =J39+'On-grid System sizing calculato'!$L$17 -> #DIV/0! | O39: =O38-G39+'On-grid System sizing calculato'!I27+$S$38 -> -1475353.3 | Q39: Estimated bill for renter (yearly) = | S39: =G37 -> 1039.71
E40: 4 | F40: =F39*(1+$G$34) -> 11361.192 | G40: =0.1*F40 -> 1136.1192 | H40: =F40/6 -> 1893.532 | I40: =G40/6 -> 189.3532 | J40: =F40-G40 -> 10225.073 | K40: =K39+F40 -> 43497.588 | L40: =L39+G40 -> 2104349.8 | M40: =M39+J40 -> -2060852.2 | N40: =J40+'On-grid System sizing calculato'!$L$17 -> #DIV/0! | O40: =O39-G40+#REF!+$S$38 -> #REF!
E41: 5 | F41: =F40*(1+$G$34) -> 11702.028 | G41: =0.1*F41 -> 1170.2028 | H41: =F41/6 -> 1950.3379 | I41: =G41/6 -> 195.03379 | J41: =F41-G41 -> 10531.825 | K41: =K40+F41 -> 55199.616 | L41: =L40+G41 -> 2105520 | M41: =M40+J41 -> -2050320.3 | N41: =J41+'On-grid System sizing calculato'!$L$17 -> #DIV/0! | O41: =O40-G41+#REF!+$S$38 -> #REF!
E42: 6 | F42: =F41*(1+$G$34) -> 12053.088 | G42: =0.1*F42 -> 1205.3088 | H42: =F42/6 -> 2008.8481 | I42: =G42/6 -> 200.88481 | J42: =F42-G42 -> 10847.78 | K42: =K41+F42 -> 67252.704 | L42: =L41+G42 -> 2106725.3 | M42: =M41+J42 -> -2039472.6 | N42: =J42+'On-grid System sizing calculato'!$L$17 -> #DIV/0! | O42: =O41-G42+#REF!+$S$38 -> #REF!
E43: 7 | F43: =F42*(1+$G$34) -> 12414.681 | G43: =0.1*F43 -> 1241.4681 | H43: =F43/6 -> 2069.1135 | I43: =G43/6 -> 206.91135 | J43: =F43-G43 -> 11173.213 | K43: =K42+F43 -> 79667.386 | L43: =L42+G43 -> 2107966.7 | M43: =M42+J43 -> -2028299.4 | N43: =J43+'On-grid System sizing calculato'!$L$17 -> #DIV/0! | O43: =O42-G43+#REF!+$S$38 -> #REF!
E44: 8 | F44: =F43*(1+$G$34) -> 12787.122 | G44: =0.1*F44 -> 1278.7122 | H44: =F44/6 -> 2131.1869 | I44: =G44/6 -> 213.11869 | J44: =F44-G44 -> 11508.409 | K44: =K43+F44 -> 92454.507 | L44: =L43+G44 -> 2109245.5 | M44: =M43+J44 -> -2016790.9 | N44: =J44+'On-grid System sizing calculato'!$L$17 -> #DIV/0! | O44: =O43-G44+#REF!+$S$38 -> #REF!
E45: 9 | F45: =F44*(1+$G$34) -> 13170.735 | G45: =0.1*F45 -> 1317.0735 | H45: =F45/6 -> 2195.1225 | I45: =G45/6 -> 219.51225 | J45: =F45-G45 -> 11853.662 | K45: =K44+F45 -> 105625.24 | L45: =L44+G45 -> 2110562.5 | M45: =M44+J45 -> -2004937.3 | N45: =J45+'On-grid System sizing calculato'!$L$17 -> #DIV/0! | O45: =O44-G45+#REF!+$S$38 -> #REF!
E46: 10 | F46: =F45*(1+$G$34) -> 13565.857 | G46: =0.1*F46 -> 1356.5857 | H46: =F46/6 -> 2260.9762 | I46: =G46/6 -> 226.09762 | J46: =F46-G46 -> 12209.272 | K46: =K45+F46 -> 119191.1 | L46: =L45+G46 -> 2111919.1 | M46: =M45+J46 -> -1992728 | N46: =J46+'On-grid System sizing calculato'!$L$17 -> #DIV/0! | O46: =O45-G46+#REF!+$S$38 -> #REF!
E47: 11 | F47: =F46*(1+$G$34) -> 13972.833 | G47: =0.1*F47 -> 1397.2833 | H47: =F47/6 -> 2328.8055 | I47: =G47/6 -> 232.88055 | J47: =F47-G47 -> 12575.55 | K47: =K46+F47 -> 133163.93 | L47: =L46+G47+C17 -> 2168116.3 | M47: =M46+J47-C17 -> -2034952.4 | N47: =J47+'On-grid System sizing calculato'!$L$17 -> #DIV/0! | O47: =O46-G47+#REF!+$S$38 -> #REF!
E48: 12 | F48: =F47*(1+$G$34) -> 14392.018 | G48: =0.1*F48 -> 1439.2018 | H48: =F48/6 -> 2398.6697 | I48: =G48/6 -> 239.86697 | J48: =F48-G48 -> 12952.816 | K48: =K47+F48 -> 147555.95 | L48: =L47+G48 -> 2169555.5 | M48: =M47+J48 -> -2021999.6 | N48: =J48+'On-grid System sizing calculato'!$L$17 -> #DIV/0! | O48: =O47-G48+#REF!+$S$38 -> #REF!
E49: 13 | F49: =F48*(1+$G$34) -> 14823.779 | G49: =0.1*F49 -> 1482.3779 | H49: =F49/6 -> 2470.6298 | I49: =G49/6 -> 247.06298 | J49: =F49-G49 -> 13341.401 | K49: =K48+F49 -> 162379.73 | L49: =L48+G49 -> 2171037.9 | M49: =M48+J49 -> -2008658.2 | N49: =J49+'On-grid System sizing calculato'!$L$17 -> #DIV/0! | O49: =O48-G49+#REF!+$S$38 -> #REF!
...

Sheet Commercial Quotation
B1: System size = | C1: 25000 | Q1: System size = | R1: 15000
B2: Items | D2: Total unit | E2: UoM | F2: Price per unit | G2: BoM Cost | H2: Margin | I2: Basic Cost | J2: GST % | K2: Final Cost | Q2: Items | S2: Total unit | T2: UoM | U2: Price per unit | V2: BoM Cost | W2: Margin | X2: Basic Cost | Y2: GST % | Z2: Final Cost
A3: Waaree | B3: Panels TOPCon non-DCR (20kW) | C3: 560 | D3: 42 | E3: nos | F3: 16 | G3: =D3*F3*C3 -> 376320 | H3: =G3*0.2 -> 75264 | I3: =G3+H3 -> 451584 | J3: 0.05 | K3: =I3*1.05 -> 474163.2 | L3: =K3/K18 -> 0.31661755 | P3: Waaree | Q3: Panels TOPCon non-DCR (20kW) | R3: 560 | S3: 30 | T3: nos | U3: 16.5 | V3: =S3*U3*R3 -> 277200 | W3: =V3*0.2 -> 55440 | X3: =V3+W3 -> 332640 | Y3: 0.05 | Z3: =X3*1.05 -> 349272 | AA3: =Z3/Z18 -> 0.16555457
A4: Solis | B4: Inverter (On-Grid) | C4: 25kW (3 ph) | D4: 1 | E4: nos | F4: 69766 | G4: =D4*F4 -> 69766 | H4: =G4*0.2 -> 13953.2 | I4: =G4+H4 -> 83719.2 | J4: 0.05 | K4: =I4*1.05 -> 87905.16 | L4: =K4/$K$18 -> 0.058697756 | P4: Solis | Q4: Inverter (On-Grid) | R4: 25kW (3 ph) | S4: 1 | T4: nos | U4: 69766 | V4: =S4*U4 -> 69766 | W4: =V4*0.3 -> 20929.8 | X4: =V4+W4 -> 90695.8 | Y4: 0.05 | Z4: =X4*1.05 -> 95230.59 | AA4: =Z4/$K$18 -> 0.063589236
A5: Deye | B5: Inverter (Hybrid) | C5: 20kW (3 ph) | D5: 1 | E5: nos | F5: 265846 | G5: =D5*F5 -> 265846 | H5: =G5*0.2 -> 53169.2 | I5: =G5+H5 -> 319015.2 | J5: 0.05 | K5: =I5*1.05 -> 334965.96 | L5: =K5/$K$18 -> 0.22367004 | P5: Deye | Q5: Inverter (Hybrid) | R5: 20kW (3 ph) | S5: 1 | T5: nos | U5: 204488 | V5: =S5*U5 -> 204488 | W5: =V5*0.3 -> 61346.4 | X5: =V5+W5 -> 265834.4 | Y5: 0.05 | Z5: =X5*1.05 -> 279126.12 | AA5: =Z5/$K$18 -> 0.18638356
A6: Deye | B6: BESS | C6: 16kWh | D6: 1 | E6: nos | F6: 203597 | G6: =F6*D6 -> 203597 | H6: =G6*0.2 -> 40719.4 | I6: =G6+H6 -> 244316.4 | J6: 0.18 | K6: =I6*1.18 -> 288293.35 | L6: =K6/$K$18 -> 0.19250489 | P6: Deye | Q6: BESS | R6: 100kWh | S6: 4 | T6: nos | U6: 200391 | V6: =U6*S6 -> 801564 | W6: =V6*0.2 -> 160312.8 | X6: =V6+W6 -> 961876.8 | Y6: 0.18 | Z6: =X6*1.18 -> 1135014.6 | AA6: =Z6/$K$18 -> 0.75789421
A7: Festa Solar | B7: DCDB | D7: 1 | E7: nos | F7: 10200 | G7: =F7*D7 -> 10200 | H7: =G7*0.3 -> 3060 | I7: =G7+H7 -> 13260 | J7: 0.18 | K7: =I7*1.18 -> 15646.8 | L7: =K7/$K$18 -> 0.010447988 | P7: Festa Solar | Q7: DCDB | S7: 1 | T7: nos | U7: 10200 | V7: =U7*S7 -> 10200 | W7: =V7*0.3 -> 3060 | X7: =V7+W7 -> 13260 | Y7: 0.18 | Z7: =X7*1.18 -> 15646.8 | AA7: =Z7/$K$18 -> 0.010447988
A8: Festa Solar | B8: ACDB | D8: 1 | E8: nos | F8: 4500 | G8: =F8*D8 -> 4500 | H8: =G8*0.3 -> 1350 | I8: =G8+H8 -> 5850 | J8: 0.18 | K8: =I8*1.18 -> 6903 | L8: =K8/$K$18 -> 0.0046094065 | P8: Festa Solar | Q8: ACDB | S8: 1 | T8: nos | U8: 14300 | V8: =U8*S8 -> 14300 | W8: =V8*0.3 -> 4290 | X8: =V8+W8 -> 18590 | Y8: 0.18 | Z8: =X8*1.18 -> 21936.2 | AA8: =Z8/$K$18 -> 0.014647669
B9: Battery box | D9: 1 | F9: 10000 | G9: =F9*D9 -> 10000 | H9: =G9*0.3 -> 3000 | I9: =G9+H9 -> 13000 | J9: 0.18 | K9: =I9*1.18 -> 15340 | L9: =K9/$K$18 -> 0.010243125 | Q9: Battery box | S9: 1 | U9: 7700 | V9: =U9*S9 -> 7700 | W9: =V9*0.3 -> 2310 | X9: =V9+W9 -> 10010 | Y9: 0.18 | Z9: =X9*1.18 -> 11811.8 | AA9: =Z9/$K$18 -> 0.0078872066
B10: Mounting structure | D10: LS | E10: LS | F10: 4000 | G10: =F10*(C1/1000) -> 100000 | H10: =G10*0.25 -> 25000 | I10: =G10+H10 -> 125000 | J10: 0.18 | K10: =I10*1.18 -> 147500 | L10: =K10/$K$18 -> 0.098491591 | Q10: Mounting structure | S10: LS | T10: LS | U10: 4000 | V10: =U10*(R1/1000) -> 60000 | W10: =V10*0.25 -> 15000 | X10: =V10+W10 -> 75000 | Y10: 0.18 | Z10: =X10*1.18 -> 88500 | AA10: =Z10/$K$18 -> 0.059094955
B11: Earthing rod | C11: 2m, dia? | D11: 3 | E11: nos | F11: 2457 | G11: =F11 -> 2457 | H11: =G11*0.2 -> 491.4 | I11: =G11+H11 -> 2948.4 | J11: 0.18 | K11: =I11*1.18 -> 3479.112 | L11: =K11/$K$18 -> 0.0023231409 | Q11: Earthing rod | R11: 2m, dia? | S11: 3 | T11: nos | U11: 2457 | V11: =U11 -> 2457 | W11: =V11*0.2 -> 491.4 | X11: =V11+W11 -> 2948.4 | Y11: 0.18 | Z11: =X11*1.18 -> 3479.112 | AA11: =Z11/$K$18 -> 0.0023231409
B12: Lightning arrestor | C12: 1m, dia? | D12: 1 | E12: nos | G12: 0 | H12: =G12*0.15 -> 0 | I12: =G12+H12 -> 0 | J12: 0.18 | K12: =I12*1.18 -> 0 | L12: =K12/$K$18 -> 0 | Q12: Lightning arrestor | R12: 1m, dia? | S12: 1 | T12: nos | V12: 0 | W12: =V12*0.15 -> 0 | X12: =V12+W12 -> 0 | Y12: 0.18 | Z12: =X12*1.18 -> 0 | AA12: =Z12/$K$18 -> 0
B13: MC4 connectors | D13: 41 | E13: nos | F13: 42 | G13: =D13*F13 -> 1722 | H13: =G13*0.2 -> 344.4 | I13: =G13+H13 -> 2066.4 | J13: 0.18 | K13: =I13*1.18 -> 2438.352 | L13: =K13/$K$18 -> 0.0016281842 | Q13: MC4 connectors | S13: 33 | T13: nos | U13: 42 | V13: =S13*U13 -> 1386 | W13: =V13*0.2 -> 277.2 | X13: =V13+W13 -> 1663.2 | Y13: 0.18 | Z13: =X13*1.18 -> 1962.576 | AA13: =Z13/$K$18 -> 0.0013104897
B14: Pins & other accessories | D14: LS | E14: LS | G14: 5000 | H14: =G14*0.4 -> 2000 | I14: =G14+H14 -> 7000 | J14: 0.18 | K14: =I14*1.18 -> 8260 | L14: =K14/$K$18 -> 0.0055155291 | Q14: Pins & other accessories | S14: LS | T14: LS | V14: 5000 | W14: =V14*0.4 -> 2000 | X14: =V14+W14 -> 7000 | Y14: 0.18 | Z14: =X14*1.18 -> 8260 | AA14: =Z14/$K$18 -> 0.0055155291
B15: Design / Installation / Logistics | D15: LS | E15: LS | F15: 4000 | G15: =F15*(C1/1000) -> 100000 | H15: =G15*0.2 -> 20000 | I15: =G15+H15 -> 120000 | J15: 0.18 | K15: =I15*1.18 -> 141600 | L15: =K15/$K$18 -> 0.094551928 | Q15: Design / Installation / Logistics | S15: LS | T15: LS | U15: 5000 | V15: =U15*(R1/1000) -> 75000 | W15: =V15*0.2 -> 15000 | X15: =V15+W15 -> 90000 | Y15: 0.18 | Z15: =X15*1.18 -> 106200 | AA15: =Z15/$K$18 -> 0.070913946
A16: 360watts | B16: IoT hub for energy automation | D16: 1 | E16: nos | F16: 0 | G16: =F16*D16 -> 0 | H16: =G16*0 -> 0 | I16: =G16+H16 -> 0 | J16: 0.18 | K16: =I16*1.18 -> 0 | L16: =K16/$K$18 -> 0 | P16: 360watts | Q16: IoT hub for energy automation | S16: 1 | T16: nos | U16: 25000 | V16: =U16*S16 -> 25000 | W16: =V16*0 -> 0 | X16: =V16+W16 -> 25000 | Y16: 0.18 | Z16: =X16*1.18 -> 29500 | AA16: =Z16/$K$18 -> 0.019698318
B17: Wiring | F17: 50000 | G17: =F17 -> 50000 | H17: =G17*0 -> 0 | I17: =G17+H17 -> 50000 | J17: 0.18 | K17: =I17*1.18 -> 59000 | L17: =K17/$K$18 -> 0.039396636 | Q17: Wiring | U17: 50000 | V17: =U17 -> 50000 | W17: =V17*0 -> 0 | X17: =V17+W17 -> 50000 | Y17: 0.18 | Z17: =X17*1.18 -> 59000 | AA17: =Z17/$K$18 -> 0.039396636
G18: =SUM(G3,G5:G17) -> 1129642 | H18: =SUM(H3,H5:H17) -> 224398.4 | I18: =SUM(I3:I17) -> 1437759.6 | K18: =SUM(K3,K5:K17) -> 1497589.8 | L18: =H18/K18 -> 0.1498397 | M18: =(K18/C1)&" / kW)" -> 59.90359104 / kW) | N18: HYBRID | O18: =K18/(Energy_Usage_kWh_3[[#TOTALS],[(2025-2026) Bill]]*0.9) -> 3.9735975 | V18: =SUM(V3,V5:V17) -> 1534295 | W18: =SUM(W3,W5:W17) -> 319527.8 | X18: =SUM(X3:X17) -> 1944518.6 | Z18: =SUM(Z3,Z5:Z17) -> 2109709.2 | AA18: =W18/Z18 -> 0.15145585 | AB18: =(Z18/R1)&" / kW)" -> 140.647282133333 / kW) | AC18: HYBRID | AD18: =Z18/(Table7[[#TOTALS],[(2025-2026) Bill]]*0.9) -> 7.439931
B19: ADDITIONAL COST: | G19: =sum(G3,G4,G7,G8,G10:G17) -> 719965 | H19: =sum(H3,H4,H7,H8,H10:H17) -> 141463 | K19: =sum(K3,K4,K7,K8,K10:K17) -> 946895.62 | L19: =H19/K19 -> 0.14939661 | M19: =(K19/C1)&" / kW)" -> 37.87582496 / kW) | N19: ON-GRID | O19: =K19/(Energy_Usage_kWh_3[[#TOTALS],[(2025-2026) Bill]]*0.65) -> 3.4787424 | Q19: ADDITIONAL COST: | W19: =sum(W3,W4,W7,W8,W10:W17) -> 116488.4 | Z19: =sum(Z3,Z4,Z7,Z8,Z10:Z17) -> 778987.28 | AA19: =W19/Z19 -> 0.14953826 | AB19: =(Z19/R1)&" / kW)" -> 51.9324852 / kW) | AC19: ON-GRID | AD19: =Z18/(Table7[[#TOTALS],[(2025-2026) Bill]]*0.3) -> 22.319793
B20: DC cable (Panels to DCDB/Inverter) | C20: 6 sq. mm
B21: AC cable (Inverter to ACDB) | C21: 6 sq. mm 4-core
B22: AC cable | C22: 4 sq mm
B23: Earthing cable | C23: DC (6 sq. mm) | E23: ~66/m
C24: DC (10 sq. mm) | E24: ~139/m
C25: AC (6 sq. mm) | E25: ~100/m
C26: AC (10 sq. mm) | E26: ~150/m
B30: QUOTATION
C32: MATTERLESS TECHNOLOGIES OPC PRIVATE LIMITED FORGE FACTORY, KCT TECHPARK, 03 ATHIPALAYAM ROAD, COIMBATORE - 641049 GST: 33AATCM6353J1ZZ PH: 9087610051
H37: =2899/1.18 -> 2456.7797
B39: To | F39: 14.03.2026
B40: Shakthi Electricals
B41: Avinashi
B44: Items | C44: Details | D44: Basic Cost | E44: GST % | F44: Final Cost
B45: Panels (Adani TOPCon / 9 panels) | C45: 615Wp | D45: 142065 | E45: 0.05 | F45: 149168.25
B46: Inverter (1-ph On-Grid) | C46: 5kW (1P) | D46: 32830 | E46: 0.05 | F46: 34471.5
B47: DCDB | C47: 1 nos | D47: 5750 | E47: 0.18 | F47: 6785
B48: ACDB | C48: 1 nos | D48: 12650 | E48: 0.18 | F48: 14927
B49: Mounting structure (GI) | C49: LS | D49: 29610 | E49: 0.18 | F49: 34939.8
B50: Earthing rod | C50: 3 nos | D50: 2760 | E50: 0.18 | F50: 3256.8
B51: Lightning arrestor | C51: 1 nos | D51: 1610 | E51: 0.18 | F51: 1899.8
...

Sheet Commercial_sizing
B3: Months | C3: (2025-2026) kWh | D3: (2025-2026) Bill | E3: Avg Rs. /kWh | F3: (2024-2025) kWh | G3: (2024-2025) Bill | H3: Avg Rs. /kWh 2 | I3: Daily kWh | K3: Column 1 | L3: Min | M3: Max | N3: units | O3: Ratio
A4: Summer | B4: April | K4: Daily Consumption (AC) | L4: =I17 -> 103.4 | M4: =I18 -> 145.66667 | N4: kWh
A5: Summer | B5: May | C5: 6961 | D5: 66547.16 | E5: =D5/C5 -> 9.56 | F5: 6568 | G5: 59998.68 | H5: =G5/F5 -> 9.135 | I5: =C5/60 -> 116.01667 | K5: Daytime energy needed (AC) | L5: =L4*$O$5 -> 82.72 | M5: =M4*$O$5 -> 116.53333 | N5: kWh | O5: 0.8
A6: Rainy | B6: June | K6: Desired AC output (from inverter) | L6: =L5/(C22*C25) -> 15.04 | M6: =M5/(C22*C25) -> 21.187879 | N6: kW
A7: Rainy | B7: July | C7: 8740 | D7: 84865.4 | E7: =D7/C7 -> 9.71 | F7: 9710 | G7: 90351.55 | H7: =G7/F7 -> 9.305 | I7: =C7/60 -> 145.66667 | K7: Power Factor (PF) | L7: 0.9 | M7: 0.9
A8: Dry / windy | B8: August | K8: Required AC output (from inverter) | L8: =L6/L7 -> 16.711111 | M8: =M6/M7 -> 23.542088 | N8: kVA | P8: Reactive power (kVA) (i.e. useful energy) = Desired AC output / PF
A9: Dry / windy | B9: September | C9: 7623 | D9: 75239.01 | E9: =D9/C9 -> 9.87 | F9: 7152 | G9: 68373.12 | H9: =G9/F9 -> 9.56 | I9: =C9/60 -> 127.05 | K9: Corresponding DC sizing | L9: =1.2*L8 -> 20.053333 | M9: =1.2*M8 -> 28.250505 | N9: kW | P9: DC/AC ratio = 1.25
A10: Rainy | B10: October
A11: Rainy | B11: November | C11: 7037 | D11: 69455.19 | E11: =D11/C11 -> 9.87 | F11: 6345 | G11: 60658.2 | H11: =G11/F11 -> 9.56 | I11: =C11/60 -> 117.28333 | K11: Panel Wp | L11: 560 | M11: 700
A12: Winter | B12: December | K12: No of panels | L12: 42 | M12: =ROUND((((System_Size_3[[#TOTALS],[Max]])*1000)/M11),0)+O12 -> 42 | N12: -3 | O12: 2
A13: Winter | B13: January | C13: 6223 | D13: 61421.01 | E13: =D13/C13 -> 9.87 | F13: 7949 | G13: 75992.44 | H13: =G13/F13 -> 9.56 | I13: =C13/60 -> 103.71667 | K13: Available inverter size (kW) | L13: 20 | M13: 25
A14: Summer | B14: February | K14: Actual DC sizing (kW) | L14: =(L12*L11)/1000 -> 23.52 | M14: =(M12*M11)/1000 -> 29.4
A15: Summer | B15: March | C15: 6204 | D15: 61233.48 | E15: =D15/C15 -> 9.87 | F15: 7253 | G15: 69338.68 | H15: =G15/F15 -> 9.56 | I15: =C15/60 -> 103.4 | K15: Actual DC/AC ratio | L15: =L14/L13 -> 1.176 | M15: =M14/M13 -> 1.176
B16: TOTAL | C16: =SUM(Energy_Usage_kWh_3[(2025-2026) kWh]) -> 42788 | D16: =SUM(Energy_Usage_kWh_3[(2025-2026) Bill]) -> 418761.25 | F16: =SUM(Energy_Usage_kWh_3[(2024-2025) kWh]) -> 44977
B17: Min = | C17: =MIN(Energy_Usage_kWh_3[(2025-2026) kWh]) -> 6204 | I17: =MIN(Energy_Usage_kWh_3[Daily kWh]) -> 103.4 | K17: Estimated BESS kWh | L17: =L4-L5 -> 20.68 | M17: =M4-M5 -> 29.133333
B18: Max = | C18: =MAX(C4:C15) -> 8740 | I18: =MAX(Energy_Usage_kWh_3[Daily kWh]) -> 145.66667 | K18: Available BESS kWh | L18: 20 | M18: 20
K19: DoD | L19: =L18*0.9 -> 18 | M19: =M18*0.9 -> 18
K20: Inverter sizing kW | L20: =L13 -> 20 | M20: 25
B21: Data needed | C21: Column 1
B22: Average peak sun hour | C22: 5.5 | K22: Estimated daytime production kWh | L22: =L13*$C$22 -> 110 | M22: =M13*$C$22 -> 137.5
B23: Total system losses (%) | C23: 25
B24: Derate factor (%) | C24: 0
B25: Performance ratio | C25: =1-(C24/100) -> 1
B29: Months | C29: (2025-2026) kWh | D29: (2025-2026) Bill | E29: Avg Rs. /kWh | F29: (2024-2025) kWh | G29: (2024-2025) Bill | H29: Avg Rs. /kWh 2 | I29: Daily kWh | K29: Column 1 | L29: Min | M29: Max | N29: units | O29: Ratio
A30: Summer | B30: April | K30: Daily Consumption (AC) | L30: =I43 -> 76.133333 | M30: =I44 -> 86.6 | N30: kWh
A31: Summer | B31: May | C31: 4671 | D31: 49792.86 | E31: =D31/C31 -> 10.66 | F31: 6568 | G31: 59998.68 | H31: =G31/F31 -> 9.135 | I31: =C31/60 -> 77.85 | K31: Daytime energy needed (AC) | L31: =L30*$O$31 -> 60.906667 | M31: =M30*$O$31 -> 69.28 | N31: kWh | O31: 0.8
A32: Rainy | B32: June | K32: Desired AC output (from inverter) | L32: =L31/(C48*C51) -> 11.073939 | M32: =M31/(C48*C51) -> 12.596364 | N32: kW
A33: Rainy | B33: July | C33: 5196 | D33: 56175.3 | E33: =D33/C33 -> 10.811259 | F33: 9710 | G33: 90351.55 | H33: =G33/F33 -> 9.305 | I33: =C33/60 -> 86.6 | K33: Power Factor (PF) | L33: 0.9 | M33: 0.9
A34: Dry / windy | B34: August | K34: Required AC output (from inverter) | L34: =L32/L33 -> 12.304377 | M34: =M32/M33 -> 13.99596 | N34: kVA | P34: Reactive power (kVA) (i.e. useful energy) = Desired AC output / PF
A35: Dry / windy | B35: September | C35: 4981 | D35: 54654.52 | E35: =D35/C35 -> 10.9726 | F35: 7152 | G35: 68373.12 | H35: =G35/F35 -> 9.56 | I35: =C35/60 -> 83.016667 | K35: Corresponding DC sizing | L35: =1.2*L34 -> 14.765253 | M35: =1.2*M34 -> 16.795152 | N35: kW | P35: DC/AC ratio = 1.25
A36: Rainy | B36: October
A37: Rainy | B37: November | C37: 4697 | D37: 51538.3 | E37: =D37/C37 -> 10.9726 | F37: 6345 | G37: 60658.2 | H37: =G37/F37 -> 9.56 | I37: =C37/60 -> 78.283333 | K37: Panel Wp | L37: 700 | M37: 560
A38: Winter | B38: December | K38: No of panels | L38: 20 | M38: =ROUND((((Table8[[#TOTALS],[Max]])*1000)/M37),0)+O38 -> 30 | O38: 0 | P38: 38
A39: Winter | B39: January | C39: 4811 | D39: 52789.18 | E39: =D39/C39 -> 10.9726 | F39: 7949 | G39: 75992.44 | H39: =G39/F39 -> 9.56 | I39: =C39/60 -> 80.183333 | K39: Available inverter size (kW) | L39: 12 | M39: 15 | P39: 18
A40: Summer | B40: February | K40: Actual DC sizing (kW) | L40: =(L38*L37)/1000 -> 14 | M40: =(M38*M37)/1000 -> 16.8 | P40: =(P38*M37)/1000 -> 21.28
A41: Summer | B41: March | C41: 4568 | D41: 50122.84 | E41: =D41/C41 -> 10.972601 | F41: 7253 | G41: 69338.68 | H41: =G41/F41 -> 9.56 | I41: =C41/60 -> 76.133333 | K41: Actual DC/AC ratio | L41: =L40/L39 -> 1.1666667 | M41: =M40/M39 -> 1.12 | P41: =P40/P39 -> 1.1822222
B42: TOTAL | C42: =SUM(Table7[(2025-2026) kWh]) -> 28924 | D42: =SUM(Table7[(2025-2026) Bill]) -> 315073 | F42: =SUM(Table7[(2024-2025) kWh]) -> 44977
B43: Min = | C43: =MIN(Table7[(2025-2026) kWh]) -> 4568 | I43: =MIN(Table7[Daily kWh]) -> 76.133333 | K43: Estimated BESS kWh | L43: =L30-L31 -> 15.226667 | M43: =M30-M31 -> 17.32
B44: Max = | C44: =MAX(C30:C41) -> 5196 | I44: =MAX(Table7[Daily kWh]) -> 86.6 | K44: Available BESS kWh | L44: 20 | M44: 20
K45: DoD | L45: =L44*0.9 -> 18 | M45: =M44*0.9 -> 18
...

Sheet Hybrid system sizing calculator
B2: 1. Analyse energy consumption for 1-2 years --> calculate per day load consumption --> Calculate solar panel & inverter sizing
B3: 2. Identify possible types of heavy loads (eg. EV vehicles, ACs, Geysers, etc.)
B4: 3. Identify loads that need backup (for comfort and partial independence from grid)
B5: 4. Calculate backup hours --> calculate BESS capacity
B8: Months | C8: 2025-2026 | D8: 2024-2025 | F8: Column 1 | G8: Normal System | H8: EV alone | I8: units
B9: April | C9: 749.11 | D9: 1051 | F9: Daily Consumption (AC) | G9: 100 | H9: =C31+C39 -> 21.085714 | I9: kWh
B10: June | C10: 705.4 | D10: 1239 | F10: Energy Needed (AC) | G10: =G9/C22 -> 100 | H10: =H9/C22 -> 21.085714 | I10: kWh
B11: August | C11: 405.58 | D11: 421 | F11: Desired AC output (from inverter) | G11: =G9/(C19*C22) -> 18.181818 | H11: =H9/(C19*C22) -> 3.8337662 | I11: kW
B12: October | C12: 415.02 | D12: 536 | F12: Power Factor (PF) | G12: 0.8 | H12: 0.99
B13: December | C13: 399 | D13: 521 | F13: Required AC output (from inverter) | G13: =G11/G12 -> 22.727273 | H13: =H11/H12 -> 3.8724911 | I13: kVA | K13: Reactive power (kVA) (i.e. useful energy) = Desired AC output / PF
B14: February | C14: 416.2 | D14: 432 | F14: Corresponding DC sizing | G14: =1.25*G13 -> 28.409091 | H14: =1.25*H13 -> 4.8406139 | I14: kW | K14: DC/AC ratio = 1.1. to 1.25
C15: =SUM(Energy_Usage_kWh_2[2025-2026]) -> 3090.31 | D15: =SUM(Energy_Usage_kWh_2[2024-2025]) -> 4200
B16: Daily consumption (kWh) = | C16: =Energy_Usage_kWh_2[[#TOTALS],[2025-2026]]/365 -> 8.4666027 | D16: =Energy_Usage_kWh_2[[#TOTALS],[2024-2025]]/365 -> 11.506849
B18: Data needed | C18: Column 1 | F18: Parameters | G18: Units | H18: Details
B19: Average peak sun hour | C19: 5.5 | G19: kWh
B20: Total system losses (%) | C20: 25
B21: Derate factor (%) | C21: 0
B22: Performance ratio | C22: =1-(C21/100) -> 1
B26: Months | C26: Energy usage (units) | D26: Column 1
B27: EV Brand name | C27: TATA Nexon | D27: MG ZS
B28: Battery Capacity | C28: 30 | D28: 45 | F28: Panels Age(Years) | G28: Expected Output N.S (KWh) | H28: Expected Output with EV (KWh)
B29: Full charging times per week | C29: 3 | D29: 4 | F29: 10 | G29: =G11*(1-0.005)^10 -> 17.292911 | H29: =H11*(1-0.005)^10 -> 3.6463339
B30: Half charging times per week | C30: 4 | D30: 3 | F30: 15 | G30: =G11*(1-0.005)^15 -> 16.86489 | H30: =H11*(1-0.005)^15 -> 3.5560826
B31: Extra power needed(KWh) per day | C31: =((C$28*1*0.9*C$29)+(C$28*0.5*0.9*C$30))/7 -> 19.285714 | D31: =((D$28*1*0.9*D$29)+(D$28*0.5*0.9*D$30))/7 -> 31.821429 | F31: 20 | G31: =G11*(1-0.005)^20 -> 16.447463 | H31: =H11*(1-0.005)^20 -> 3.4680651
G33: w/o EV | H33: with EV
B34: Months | C34: Energy usage (units) | F34: Panel Wp | G34: 620 | H34: 615
B35: EV Brand name | F35: No of panels | G35: =ROUND(((G14*1000)/G34),0) -> 46 | H35: =ROUND((((System_Size_2[[#TOTALS],[Normal System]]+System_Size_2[[#TOTALS],[EV alone]])*1000)/H34),0) -> 54
B36: Battery Capacity | C36: 3.5 | F36: Actual DC sizing (kW) | G36: =(G35*G34)/1000 -> 28.52 | H36: =(H35*H34)/1000 -> 33.21
B37: Full charging times per week | C37: 4 | F37: Actual DC/AC ratio | G37: =G36/G13 -> 1.25488 | H37: =H36/(G13+H13) -> 1.2485073
B38: Half charging times per week | C38: 3 | F38: Available inverter size (kW) | G38: 3 | H38: 6
B39: Extra power needed(KWh) per day | C39: =(C36*0.9*C37)/7 -> 1.8 | F39: Final no of panels | G39: 4 | H39: =if((H38>H36),H35+1,H35) -> 54
F40: Final system size (kW) | G40: =(G34*G39)/1000 -> 2.48 | H40: =(H34*H39)/1000 -> 33.21
F45: Hours | H45: Load kWh | L45: BESS kWh
C46: Loads | F46: MIN | G46: MAX | H46: MIN | I46: MAX | J46: Total kWh consumption | L46: MIN | M46: MAX
B47: All months | C47: Critical | H47: 10 | I47: 15 | J47: =I47 -> 15 | K47: into consideration | L47: =H47/($C$59*$C$60) -> 12.345679 | M47: =I47/($C$59*$C$60) -> 18.518519 | N47: (Lighting, Fan, Fridge, Security cameras, Gate automation, ... )
B48: Summer months | C48: HVAC | D48: Low solar hours | E48: Morning (6am to 10am) | F48: 2 | G48: 4 | H48: =F48*$C$57 -> 40 | I48: =G48*$C$57 -> 80 | K48: not into consideration | L48: =H48/($C$59*$C$60) -> 49.382716 | M48: =I48/($C$59*$C$60) -> 98.765432
C49: HVAC | D49: High solar hours | E49: Late morning/afternoon (10am to 5pm) | F49: 4 | G49: 7 | H49: =F49*$C$57 -> 80 | I49: =G49*$C$57 -> 140 | K49: not into consideration | L49: =H49/($C$59*$C$60) -> 98.765432 | M49: =I49/($C$59*$C$60) -> 172.83951
C50: HVAC | D50: Non-solar hours | E50: Evening/night (5pm to 6am) | F50: 6 | G50: 13 | H50: =F50*$C$57 -> 120 | I50: =G50*$C$57 -> 260 | J50: 180 | K50: into consideration | L50: =H50/($C$59*$C$60) -> 148.14815 | M50: =I50/($C$59*$C$60) -> 320.98765
B51: Non-summer months | C51: HVAC | D51: Low solar hours | E51: Morning (6am to 10am) | F51: 0 | G51: 1 | H51: =F51*$C$57 -> 0 | I51: =G51*$C$57 -> 20 | K51: not into consideration | L51: =H51/($C$59*$C$60) -> 0 | M51: =I51/($C$59*$C$60) -> 24.691358
C52: HVAC | D52: High solar hours | E52: Late morning/afternoon (10am to 5pm) | F52: 0 | G52: 2 | H52: =F52*$C$57 -> 0 | I52: =G52*$C$57 -> 40 | K52: not into consideration | L52: =H52/($C$59*$C$60) -> 0 | M52: =I52/($C$59*$C$60) -> 49.382716
...

Sheet DCDB & ACDB
B5: Parameters | C5: Values | D5: Units | F5: Parameters | G5: Values | H5: Units
B6: System capacity | C6: 5 | D6: KW | F6: System capacity | G6: 4 | H6: KW
B7: DC input voltage | C7: 400 | D7: V | F7: AC supply voltage | G7: 415 | H7: V
F8: Phase | G8: 3 | H8: ø
B9: Saftey Factor | C9: 0.3
F10: AC fuse rating | G10: =(G6*1000/(SQRT(3)*415*1))*(1+C9) -> 7.2342684 | H10: A
B12: DC fuse rating | C12: =(C6*1000/C7)*(1+C9) -> 16.25 | D12: A
G15: (System Size /SQRT(phase) * AC Input V * power factor )*(Safety factor )
B16: SPD RATING
B17: More than 600V in string | C17: 1000V
B18: Less than 600V in string | C18: 600V

Sheet Battery sizing
B4: Appliances | C4: NOs | D4: power(W) | E4: Total power | F4: No of hours | G4: energy (Wh)
B5: Lights | C5: 5 | D5: 10 | E5: =C5*D5 -> 50 | F5: 6 | G5: =C5*(D5*F5) -> 300
B6: Fan | C6: 4 | D6: 70 | E6: =C6*D6 -> 280 | F6: 6 | G6: =C6*(D6*F6) -> 1680 | I6: daily consumption x day of atonomy /D.O.D x System voltage
B7: TV | C7: 1 | D7: 150 | E7: =C7*D7 -> 150 | F7: 2 | G7: =C7*(D7*F7) -> 300
B8: AC | C8: 2 | D8: 1500 | E8: =C8*D8 -> 3000 | F8: 2 | G8: =C8*(D8*F8) -> 6000
B9: Chargers | C9: 3 | D9: 10 | E9: =C9*D9 -> 30 | F9: 2 | G9: =C9*(D9*F9) -> 60
B10: Refrigerator | C10: 1 | D10: 150 | E10: =C10*D10 -> 150 | F10: 3 | G10: =C10*(D10*F10) -> 450
B11: Computers | C11: 1 | D11: 250 | E11: =C11*D11 -> 250 | F11: 6 | G11: =C11*(D11*F11) -> 1500
B12: Others | C12: 1 | D12: 300 | E12: =C12*D12 -> 300 | F12: 2 | G12: =C12*(D12*F12) -> 600
B13: Total | E13: =SUM(E5:E12) -> 4210 | G13: =SUM(G5:G12) -> 10890
B21: Mode | C21: Energy used (WH) | D21: Bateery needed (Kwh) | E21: battery V | F21: Battery AH | G21: Total capacity | H21: Column 1 | I21: Run time | J21: Run Time(h) (3.3KWH) | K21: Run Time(h) (4.1KWH) | L21: Run Time(h) (8KWH)
B22: Basic - Lights & Fans | C22: =sum(G5,G6) -> 1980 | D22: =(((C22*1.3)/(0.8*24))*24)/1000 -> 3.2175 | E22: 24 | F22: =((C22*1.3)/(0.8*24)) -> 134.0625 | G22: =(E22*F22)/1000 -> 3.2175 | I22: =D22/(sum(E5,E6)/1000) -> 9.75 | J22: =D22/(sum(E5,E6)/1000) -> 9.75 | K22: =D23/(sum(E5,E6)/1000) -> 12.261364 | L22: =D24/(sum(E5,E6)/1000) -> 53.625
B23: Semi Advanced - Lights , Fans , Refrigerator,charges | C23: =sum(G5,G6,G10,G9) -> 2490 | D23: =(((C23*1.3)/(0.8*24))*24)/1000 -> 4.04625 | E23: 24 | F23: =((C23*1.3)/(0.8*24)) -> 168.59375 | G23: =(E23*F23)/1000 -> 4.04625 | I23: =D23/(sum(E5,E6,E10,E9)/1000) -> 7.9338235 | J23: =D22/(sum(E5,E6,E10,E9)/1000) -> 6.3088235 | K23: =D23/(sum(E5,E6,E10,E9)/1000) -> 7.9338235 | L23: =D24/(sum(E5,E6,E9,E10)/1000) -> 34.698529
B24: Advanced - All | C24: =sum(G5:G12) -> 10890 | D24: =(((C24*1.3)/(0.8*48))*48)/1000 -> 17.69625 | E24: 48 | F24: =((C24*1.3)/(0.8*48)) -> 368.67188 | G24: =(E24*F24)/1000 -> 17.69625 | I24: =D24/(sum(E5:E12)/1000) -> 4.2033848 | J24: =D22/((sum(E5:E12))/1000) -> 0.76425178 | K24: =D23/(sum(E5:E12)/1000) -> 0.96110451 | L24: =D24/(sum(E5:E12)/1000) -> 4.2033848

Sheet Wiring 
E3: Practical DC WIRING SIZING
B4: Panels Specs | C4: Values(V&I)
B5: Vmp | C5: 23 | E5: CURRENT/DISTANCE | F5: 10m | G5: 25m | H5: 50m | I5: 100m | K5: Indian Standards for DC Cables: • Minimum DC cable size: 4mm² • Voltage drop limit: 2% for DC circuits • Material: XLPE or XLPO insulated copper cables • Standards: IS 7098 Part I & II
B6: Imp | C6: 12 | E6: 10A | F6: 2.5 | G6: 4 | H6: 6 | I6: 16
E7: 20A | F7: 4 | G7: 6 | H7: 16 | I7: 25
E8: 30A | F8: 6 | G8: 10 | H8: 25 | I8: 35
E9: 40A | F9: 10 | G9: 16 | H9: 35 | I9: 50
B10: No of panels in a string | C10: 4 | E10: 50A | F10: 16 | G10: 25 | H10: 50 | I10: 70
B11: No of Strings | C11: 2
B13: Safety factor | C13: 1.25
E15: Practical AC WIRING SIZING
E17: CURRENT/DISTANCE | F17: 10m | G17: 25m | H17: 50m | I17: 100m | K17: Indian Standards for AC Cables: • Minimum AC cable size: 4mm² • Voltage drop limit: 2% from inverter to distribution board • Material: PVC or XLPE insulated copper cables • Neutral wire: Same size as phase wires in 3-phase systems
B18: Copper quick ref (20 °C, Ω/m): 2.5 mm²: 0.00741 4 mm²: 0.00461 6 mm²: 0.00308 10 mm²: 0.00183 16 mm²: 0.00115 | E18: 16A | F18: 2.5 | G18: 2.5 | H18: 4 | I18: 6
E19: 25A | F19: 2.5 | G19: 4 | H19: 6 | I19: 10
E20: 32A | F20: 4 | G20: 6 | H20: 10 | I20: 16
E21: 40A | F21: 6 | G21: 10 | H21: 16 | I21: 25
E22: 63A | F22: 10 | G22: 16 | H22: 25 | I22: 35
B27: DC Wire Sizing | C27: Values 1 | D27: Units
B28: Isc | C28: 11 | D28: A
B29: safety Factor And Contionous Load | C29: 1.56 | D29: %
B30: Current | C30: =C28*C29 -> 17.16 | D30: A
B31: Length | C31: 10 | D31: L
B32: Panel Voltage Vmmp | C32: 42.5 | D32: V
B33: No of Pnaels | C33: 8
B34: System Voltage | C34: =C32*C33 -> 340 | D34: V
B35: Voltage Drop | C35: =2*C31*C30*0.00461 -> 1.582152 | D35: V
B36: Recomonded less than 2 % | C36: =(C35/C34)*100 -> 0.46533882 | D36: %
B41: AC Wire Sizing | C41: Values 2 | D41: Units
B42: Output Power | C42: 5000 | D42: W
B43: Voltage | C43: 230 | D43: A
B44: Efficiency | C44: 0.97 | D44: %
B45: Power Factor | C45: 0.9 | D45: A
B46: Current | C46: =C42/C43*C44*C45 -> 18.978261 | D46: A
B47: Length | C47: 10 | D47: L
B48: Voltage Drop | C48: =2*C47*C46*0.00461 -> 1.7497957 | D48: V
B49: Recomonded less than 2 % | C49: =(C48/C43)*100 -> 0.76078072 | D49: %
B50: Voltage Drop 3 phase | C50: =(SQRT(3))*C47*C46*0.00461 -> 1.5153675

Sheet Missmatch loss 
B4: Parameter | C4: Reliance HJT 700Wp | D4: Renewsys TOPCon (585Wp) | E4: units | F4: Difference
B5: Pmax | C5: 700 | D5: 585 | E5: Wp | F5: HJT +20% power
B6: Vmpp | C6: 41.5 | D6: 42.87 | E6: V | F6: 3.3% (TOPCon higher V)
B7: Impp | C7: =C5/C6 -> 16.86747 | D7: =D5/D6 -> 13.645906 | E7: A | F7: HJT +23.6% current
B8: Voc | C8: 49.5 | D8: 52.3 | E8: V | F8: 5.7% (TOPCon higher)
B9: Isc | C9: 17.8 | D9: 13.75 | E9: A | F9: HJT +29.5% short-circuit
B12: String | C12: Voltage (6xVmpp) | D12: Current (Impp) | E12: Power Output(Kw)
B13: HJT | C13: 249 | D13: 16.86 | E13: =(C13*D13)/1000 -> 4.19814
B14: TOPCon | C14: 257 | D14: 13.64 | E14: =(C14*D14)/1000 -> 3.50548
B15: Theoretical Total | E15: =SUM(Table10[Power Output(Kw)]) -> 7.70362
B18: BEFORE Mismatch: 7.7 kW total AFTER Clipping: HJT clipped to 13.64A - 249V × 13.64A = 3.4 kW (loss 19.1%) TOPCon unchanged: 3.5 kW NEW TOTAL: 6.9 kW Mismatch Loss: 10.4% (800W lost)

Sheet Enphase
A1: System size = | B1: 8000
